Workbook

Sheet 1. Original Dataset
A1: ORIGINAL DATASET (preserved, unmodified — store_performance)
A2: 320 rows • 80 stores • 4 months (Jan–Apr 2025) • Source: business_regression_data.xlsx
A4: store_id | B4: month | C4: region | D4: store_type | E4: marketing_spend | F4: footfall | G4: avg_discount_pct | H4: staff_count | I4: inventory_availability_pct | J4: competitor_distance_km | K4: holiday_flag | L4: customer_rating | M4: monthly_sales | N4: monthly_profit
A5: STR-1001 | B5: 2025-01 | C5: East | D5: Residential | E5: 70389.11 | F5: 8302 | G5: 0.042 | H5: 17 | I5: 75 | J5: 5.28 | K5: 1 | L5: 3.1 | M5: 658832.62 | N5: 84349.93
A6: STR-1001 | B6: 2025-02 | C6: East | D6: Residential | E6: 43827.89 | F6: 8487 | G6: 0.168 | H6: 23 | I6: 84.4 | J6: 4.31 | K6: 0 | L6: 2.8 | M6: 634436 | N6: 106130.54
A7: STR-1001 | B7: 2025-03 | C7: East | D7: Residential | E7: 59921.75 | F7: 9113 | G7: 0.133 | H7: 20 | I7: 88 | J7: 12 | K7: 0 | L7: 3.2 | M7: 678722.06 | N7: 101883.86
A8: STR-1001 | B8: 2025-04 | C8: East | D8: Residential | E8: 56856.63 | F8: 9431 | G8: 0.142 | H8: 23 | I8: 86.9 | J8: 4.97 | K8: 0 | L8: 3.4 | M8: 658920.3 | N8: 97910.37
A9: STR-1002 | B9: 2025-01 | C9: East | D9: High Street | E9: 48412.64 | F9: 9545 | G9: 0.231 | H9: 21 | I9: 97.6 | J9: 6.94 | K9: 1 | L9: 4.2 | M9: 741341.44 | N9: 119208.17
A10: STR-1002 | B10: 2025-02 | C10: East | D10: High Street | E10: 64811.21 | F10: 9792 | G10: 0.112 | H10: 20 | I10: 84.2 | J10: 2.88 | K10: 0 | L10: 4.2 | M10: 761835.34 | N10: 149602.23
A11: STR-1002 | B11: 2025-03 | C11: East | D11: High Street | E11: 46213.45 | F11: 10616 | G11: 0.122 | H11: 22 | I11: 85.2 | J11: 0.2 | K11: 1 | L11: 4.1 | M11: 806615.54 | N11: 131364.62
A12: STR-1002 | B12: 2025-04 | C12: East | D12: High Street | E12: 68148.52 | F12: 8567 | G12: 0.127 | H12: 23 | I12: 95.6 | J12: 0.8 | K12: 0 | L12: 3.9 | M12: 850164.26 | N12: 149262.75
A13: STR-1003 | B13: 2025-01 | C13: North | D13: Airport | E13: 71838.86 | F13: 10979 | G13: 0.215 | H13: 26 | I13: 88.6 | J13: 7.7 | K13: 1 | L13: 3.8 | M13: 930581.7 | N13: 136207.98
A14: STR-1003 | B14: 2025-02 | C14: North | D14: Airport | E14: 68133.44 | F14: 9459 | G14: 0.22 | H14: 21 | I14: 85 | J14: 1.91 | K14: 0 | L14: 4.2 | M14: 779010.94 | N14: 106328.09
A15: STR-1003 | B15: 2025-03 | C15: North | D15: Airport | E15: 34285.21 | F15: 9172 | G15: 0.213 | H15: 22 | I15: 88.3 | J15: 10.46 | K15: 1 | L15: 3.8 | M15: 723060.76 | N15: 123131.24
A16: STR-1003 | B16: 2025-04 | C16: North | D16: Airport | E16: 67979.88 | F16: 11230 | G16: 0.002 | H16: 28 | I16: 85.3 | J16: 7.16 | K16: 0 | L16: 3.8 | M16: 910791.94 | N16: 158891.28
... A37: STR-1009 | B37: 2025-01 | C37: North | D37: Residential | E37: 54597.83 | F37: 9429 | G37: 0.188 | H37: 21 | I37: 83.3 | J37: 11.71 | K37: 0 | L37: 4.2 | M37: 641865.03 | N37: 81342.58
A38: STR-1009 | B38: 2025-02 | C38: North | D38: Residential | E38: 73771.91 | F38: 11695 | G38: 0.07 | H38: 25 | I38: 84.7 | J38: 0.62 | K38: 0 | M38: 799477.76 | N38: 164974.41
A39: STR-1009 | B39: 2025-03 | C39: North | D39: Residential | E39: 74413.88 | F39: 9449 | G39: 0.039 | H39: 23 | I39: 92.1 | J39: 2.12 | K39: 0 | L39: 3.5 | M39: 798952.17 | N39: 161499.04
A40: STR-1009 | B40: 2025-04 | C40: North | D40: Residential | E40: 52483.77 | F40: 10453 | G40: 0.247 | H40: 25 | I40: 99 | J40: 6.31 | K40: 0 | L40: 3.6 | M40: 800979.78 | N40: 149242.27
A41: STR-1010 | B41: 2025-01 | C41: North | D41: Mall | E41: 75269.87 | F41: 8838 | G41: 0.092 | H41: 21 | I41: 83.1 | J41: 9.56 | K41: 1 | L41: 4.2 | M41: 820593.93 | N41: 115860.06
A42: STR-1010 | B42: 2025-02 | C42: North | D42: Mall | E42: 61245.41 | F42: 8156 | G42: 0.156 | H42: 19 | I42: 92.9 | J42: 9.05 | K42: 0 | L42: 3.8 | M42: 718330.53 | N42: 93247.9
A43: STR-1010 | B43: 2025-03 | C43: North | D43: Mall | E43: 93381.26 | F43: 7562 | G43: 0.198 | H43: 19 | I43: 82.9 | J43: 5.05 | K43: 0 | L43: 4 | M43: 736633.4 | N43: 115654.66
A44: STR-1010 | B44: 2025-04 | C44: North | D44: Mall | E44: 65012.19 | F44: 9598 | G44: 0.085 | H44: 24 | I44: 98.3 | J44: 0.89 | K44: 0 | L44: 3.8 | M44: 828623.85 | N44: 167320.52
A45: STR-1011 | B45: 2025-01 | C45: East | D45: Mall | E45: 40462.94 | F45: 3660 | G45: 0.218 | H45: 11 | I45: 95.2 | J45: 5.57 | K45: 0 | L45: 4.4 | M45: 592195.85 | N45: 92291.56
A46: STR-1011 | B46: 2025-02 | C46: East | D46: Mall | E46: 46123.88 | F46: 3227 | G46: 0.143 | H46: 10 | I46: 75.4 | J46: 1.06 | K46: 0 | L46: 4.4 | M46: 532644.46 | N46: 60681.32
A47: STR-1011 | B47: 2025-03 | C47: East | D47: Mall | E47: 68077.54 | F47: 3360 | G47: 0.128 | H47: 14 | I47: 88.2 | J47: 1.24 | K47: 1 | L47: 4 | M47: 657429.18 | N47: 88919.74
A48: STR-1011 | B48: 2025-04 | C48: East | D48: Mall | E48: 64882.14 | F48: 3642 | G48: 0.019 | H48: 13 | I48: 87.8 | J48: 4.52 | K48: 0 | L48: 4.2 | M48: 605178 | N48: 106958.74
A49: STR-1012 | B49: 2025-01 | C49: West | D49: Residential | E49: 138855.51 | F49: 5145 | G49: 0.06 | H49: 17 | I49: 88.2 | J49: 9.58 | K49: 0 | L49: 3.2 | M49: 595467.6 | N49: 104276.46
A50: STR-1012 | B50: 2025-02 | C50: West | D50: Residential | E50: 63630.21 | F50: 4460 | G50: 0.235 | H50: 14 | I50: 98.6 | J50: 5.52 | K50: 0 | L50: 3.5 | M50: 599603.4 | N50: 112685.12
... A75: STR-1018 | B75: 2025-03 | C75: East | D75: High Street | E75: 60571.82 | F75: 3193 | G75: 0.197 | H75: 7 | I75: 99 | J75: 1.43 | K75: 0 | L75: 3.2 | M75: 605023.87 | N75: 98545.81
A76: STR-1018 | B76: 2025-04 | C76: East | D76: High Street | E76: 55081.16 | F76: 5485 | G76: 0.036 | H76: 12 | I76: 88 | K76: 0 | L76: 3.5 | M76: 674774.09 | N76: 141917.59
A77: STR-1019 | B77: 2025-01 | C77: East | D77: Residential | E77: 46201.46 | F77: 5918 | G77: 0.277 | H77: 13 | I77: 78.8 | J77: 4.91 | K77: 0 | L77: 4.5 | M77: 616069.41 | N77: 54453.99
A78: STR-1019 | B78: 2025-02 | C78: East | D78: Residential | E78: 53762.92 | F78: 6821 | G78: 0.066 | H78: 19 | I78: 94.6 | J78: 7.03 | K78: 0 | L78: 4.4 | M78: 630829.94 | N78: 117090.02
A79: STR-1019 | B79: 2025-03 | C79: East | D79: Residential | E79: 70144.78 | F79: 6806 | G79: 0.178 | H79: 20 | I79: 93.1 | J79: 0.28 | K79: 1 | L79: 4.3 | M79: 788087.68 | N79: 116803.42
A80: STR-1019 | B80: 2025-04 | C80: East | D80: Residential | E80: 58749.63 | F80: 8252 | G80: 0.203 | H80: 20 | I80: 85.2 | J80: 3.61 | K80: 0 | L80: 4.5 | M80: 680840.36 | N80: 68007.68
A81: STR-1020 | B81: 2025-01 | C81: South | D81: High Street | E81: 56973.18 | F81: 6662 | G81: 0.1 | H81: 15 | I81: 77.7 | J81: 7.52 | K81: 1 | L81: 3.2 | M81: 643657.47 | N81: 87022.45
A82: STR-1020 | B82: 2025-02 | C82: South | D82: High Street | E82: 54872.82 | F82: 5962 | G82: 0.064 | H82: 12 | I82: 85.4 | J82: 2.58 | K82: 0 | L82: 2.9 | M82: 691112.6 | N82: 109212.83
A83: STR-1020 | B83: 2025-03 | C83: South | D83: High Street | E83: 80562.81 | F83: 7470 | G83: 0.172 | H83: 16 | I83: 83.5 | J83: 2.29 | K83: 0 | L83: 3.3 | M83: 776922.17 | N83: 150701.93
A84: STR-1020 | B84: 2025-04 | C84: South | D84: High Street | E84: 77999.9 | F84: 5974 | G84: 0.252 | H84: 14 | I84: 81.3 | J84: 2.39 | K84: 0 | L84: 3.2 | M84: 636561.34 | N84: 93861.06
A85: STR-1021 | B85: 2025-01 | C85: West | D85: Mall | E85: 60881.01 | F85: 5410 | G85: 0.179 | H85: 15 | I85: 83.9 | J85: 5.24 | K85: 0 | L85: 4.6 | M85: 621369.58 | N85: 85493.64
...

Sheet 2. Cleaned Data
A1: CLEANED DATA & QUALITY CHECKS
A3: DATA-QUALITY CHECKLIST
A4: Check | B4: Result | C4: Action taken
A5: Missing values | B5: competitor_distance_km: 6 missing | customer_rating: 8 missing | C5: Imputed with group medians (region / store_type). 0 missing after.
A6: Duplicate rows | B6: 0 duplicates found | C6: None to remove.
A7: Data types | B7: All columns typed correctly (numeric/categorical/date) | C7: month parsed as date; ids/region/store_type as text.
A8: Outliers (IQR) | B8: marketing_spend: 6 | competitor_distance_km: 15 | inventory_avail: 7 | staff_count: 1 | profit: 1 | C8: Flagged & retained (plausible real values; not deleted).
A10: OUTLIER SUMMARY (1.5×IQR rule)
A11: Variable | B11: Min | C11: Max | D11: Lower fence | E11: Upper fence | F11: # Outliers
A12: marketing_spend | B12: 9534.65 | C12: 172415.52 | D12: 6941.6813 | E12: 104898.13 | F12: 6
A13: footfall | B13: 971 | C13: 12870 | D13: -1214.25 | E13: 14317.75 | F13: 0
A14: avg_discount_pct | B14: 0 | C14: 0.292 | D14: -0.075 | E14: 0.319 | F14: 0
A15: staff_count | B15: 5 | C15: 31 | D15: 2.5 | E15: 30.5 | F15: 1
A16: inventory_availability_pct | B16: 71 | C16: 99 | D16: 75.175 | E16: 101.775 | F16: 7
A17: competitor_distance_km | B17: 0.2 | C17: 22.02 | D17: -6 | E17: 13.6 | F17: 15
A18: customer_rating | B18: 2.8 | C18: 5 | D18: 2.3 | E18: 5.5 | F18: 0
A19: monthly_sales | B19: 400831.65 | C19: 946833.54 | D19: 392200.54 | E19: 971495.84 | F19: 0
A20: monthly_profit | B20: 53544.36 | C20: 200575.34 | D20: 32519.864 | E20: 189671.29 | F20: 1
A22: CLEANED DATASET (imputed; used for modelling)
A23: store_id | B23: month | C23: region | D23: store_type | E23: marketing_spend | F23: footfall | G23: avg_discount_pct | H23: staff_count | I23: inventory_availability_pct | J23: competitor_distance_km | K23: holiday_flag | L23: customer_rating | M23: monthly_sales | N23: monthly_profit
A24: STR-1001 | B24: 2025-01 | C24: East | D24: Residential | E24: 70389.11 | F24: 8302 | G24: 0.042 | H24: 17 | I24: 75 | J24: 5.28 | K24: 1 | L24: 3.1 | M24: 658832.62 | N24: 84349.93
A25: STR-1001 | B25: 2025-02 | C25: East | D25: Residential | E25: 43827.89 | F25: 8487 | G25: 0.168 | H25: 23 | I25: 84.4 | J25: 4.31 | K25: 0 | L25: 2.8 | M25: 634436 | N25: 106130.54
A26: STR-1001 | B26: 2025-03 | C26: East | D26: Residential | E26: 59921.75 | F26: 9113 | G26: 0.133 | H26: 20 | I26: 88 | J26: 12 | K26: 0 | L26: 3.2 | M26: 678722.06 | N26: 101883.86
A27: STR-1001 | B27: 2025-04 | C27: East | D27: Residential | E27: 56856.63 | F27: 9431 | G27: 0.142 | H27: 23 | I27: 86.9 | J27: 4.97 | K27: 0 | L27: 3.4 | M27: 658920.3 | N27: 97910.37
A28: STR-1002 | B28: 2025-01 | C28: East | D28: High Street | E28: 48412.64 | F28: 9545 | G28: 0.231 | H28: 21 | I28: 97.6 | J28: 6.94 | K28: 1 | L28: 4.2 | M28: 741341.44 | N28: 119208.17
A29: STR-1002 | B29: 2025-02 | C29: East | D29: High Street | E29: 64811.21 | F29: 9792 | G29: 0.112 | H29: 20 | I29: 84.2 | J29: 2.88 | K29: 0 | L29: 4.2 | M29: 761835.34 | N29: 149602.23
A30: STR-1002 | B30: 2025-03 | C30: East | D30: High Street | E30: 46213.45 | F30: 10616 | G30: 0.122 | H30: 22 | I30: 85.2 | J30: 0.2 | K30: 1 | L30: 4.1 | M30: 806615.54 | N30: 131364.62
A31: STR-1002 | B31: 2025-04 | C31: East | D31: High Street | E31: 68148.52 | F31: 8567 | G31: 0.127 | H31: 23 | I31: 95.6 | J31: 0.8 | K31: 0 | L31: 3.9 | M31: 850164.26 | N31: 149262.75
A32: STR-1003 | B32: 2025-01 | C32: North | D32: Airport | E32: 71838.86 | F32: 10979 | G32: 0.215 | H32: 26 | I32: 88.6 | J32: 7.7 | K32: 1 | L32: 3.8 | M32: 930581.7 | N32: 136207.98
A33: STR-1003 | B33: 2025-02 | C33: North | D33: Airport | E33: 68133.44 | F33: 9459 | G33: 0.22 | H33: 21 | I33: 85 | J33: 1.91 | K33: 0 | L33: 4.2 | M33: 779010.94 | N33: 106328.09
A34: STR-1003 | B34: 2025-03 | C34: North | D34: Airport | E34: 34285.21 | F34: 9172 | G34: 0.213 | H34: 22 | I34: 88.3 | J34: 10.46 | K34: 1 | L34: 3.8 | M34: 723060.76 | N34: 123131.24
A35: STR-1003 | B35: 2025-04 | C35: North | D35: Airport | E35: 67979.88 | F35: 11230 | G35: 0.002 | H35: 28 | I35: 85.3 | J35: 7.16 | K35: 0 | L35: 3.8 | M35: 910791.94 | N35: 158891.28
... A343: STR-1080 | B343: 2025-04 | C343: East | D343: Residential | E343: 40553.11 | F343: 5317 | G343: 0.165 | H343: 17 | I343: 84.3 | J343: 11.82 | K343: 0 | L343: 4.1 | M343: 559660.84 | N343: 71443.61

Sheet 3. Dummy Variables
A1: DUMMY VARIABLES — Store Type (reference = High Street)
A3: • Categorical chosen: store_type (4 levels: High Street, Residential, Mall, Airport).
A4: • Reference category = HIGH STREET — it is the most frequent level (116 of 320 rows = 36%), giving the most stable baseline.
A5: • Three dummies created (Airport, Mall, Residential). High Street is OMITTED to avoid the dummy-variable trap (perfect collinearity with the intercept).
A6: • Each dummy coefficient is read as the sales difference vs an otherwise-identical High Street store.
A8: Store Type | B8: Count | C8: Role in model
A9: High Street | B9: 116 | C9: Reference (omitted)
A10: Residential | B10: 100 | C10: Dummy
A11: Mall | B11: 76 | C11: Dummy
A12: Airport | B12: 28 | C12: Dummy
A14: ENCODED PREVIEW (1 = belongs to that store type, 0 = otherwise)
A15: store_id | B15: month | C15: store_type | D15: st_Airport | E15: st_Mall | F15: st_Residential
A16: STR-1001 | B16: 2025-01 | C16: Residential | D16: 0 | E16: 0 | F16: 1
A17: STR-1001 | B17: 2025-02 | C17: Residential | D17: 0 | E17: 0 | F17: 1
A18: STR-1001 | B18: 2025-03 | C18: Residential | D18: 0 | E18: 0 | F18: 1
A19: STR-1001 | B19: 2025-04 | C19: Residential | D19: 0 | E19: 0 | F19: 1
A20: STR-1002 | B20: 2025-01 | C20: High Street | D20: 0 | E20: 0 | F20: 0
A21: STR-1002 | B21: 2025-02 | C21: High Street | D21: 0 | E21: 0 | F21: 0
A22: STR-1002 | B22: 2025-03 | C22: High Street | D22: 0 | E22: 0 | F22: 0
A23: STR-1002 | B23: 2025-04 | C23: High Street | D23: 0 | E23: 0 | F23: 0
A24: STR-1003 | B24: 2025-01 | C24: Airport | D24: 1 | E24: 0 | F24: 0
A25: STR-1003 | B25: 2025-02 | C25: Airport | D25: 1 | E25: 0 | F25: 0
A26: STR-1003 | B26: 2025-03 | C26: Airport | D26: 1 | E26: 0 | F26: 0
A27: STR-1003 | B27: 2025-04 | C27: Airport | D27: 1 | E27: 0 | F27: 0
... A35: STR-1005 | B35: 2025-04 | C35: Residential | D35: 0 | E35: 0 | F35: 1

Sheet 4. Simple Regression 1
A1: SIMPLE REGRESSION 1 — Sales vs Footfall
A3: MODEL FIT
A4: Observations | B4: 320
A5: R² | B5: 0.7363
A6: Adjusted R² | B6: 0.7355
A7: F-statistic | B7: 887.8488
A8: Prob (F-statistic) | B8: 4.75e-94
A9: Residual Std Error (RMSE) | B9: 53373.74
A10: AIC | B10: 7876.56
A12: COEFFICIENTS
A13: Term | B13: Coefficient | C13: Std Error | D13: t-stat | E13: P-value | F13: 95% CI Low | G13: 95% CI High
A14: const | B14: 446410.58 | C14: 8407.7383 | D14: 53.0952 | E14: 0 | F14: 429868.76 | G14: 462952.4
A15: footfall | B15: 35.678031 | C15: 1.197378 | D15: 29.7968 | E15: 0 | F15: 33.322247 | G15: 38.033815
A16: Green P-value = significant (p<0.05) Amber = not significant
A18: BUSINESS INTERPRETATION
A19: Equation: Monthly Sales = 446,411 + 35.68 × Footfall
A20: Each extra customer visit (footfall) is associated with about ₹35.7 more in monthly sales.
A21: Footfall alone explains 73.6% of the variation in sales (R²=0.7363). Strongly significant (p<0.001, F=888).
A22: Verdict: statistically significant AND practically useful — footfall is the single best one-variable predictor.

Sheet 5. Simple Regression 2
A1: SIMPLE REGRESSION 2 — Sales vs Marketing Spend
A3: MODEL FIT
A4: Observations | B4: 320
A5: R² | B5: 0.1672
A6: Adjusted R² | B6: 0.1646
A7: F-statistic | B7: 63.8649
A8: Prob (F-statistic) | B8: 2.48e-14
A9: Residual Std Error (RMSE) | B9: 94846.03
A10: AIC | B10: 8244.52
A12: COEFFICIENTS
A13: Term | B13: Coefficient | C13: Std Error | D13: t-stat | E13: P-value | F13: 95% CI Low | G13: 95% CI High
A14: const | B14: 560777.35 | C14: 15906.906 | D14: 35.2537 | E14: 0 | F14: 529481.27 | G14: 592073.42
A15: marketing_spend | B15: 2.129575 | C15: 0.266478 | D15: 7.9916 | E15: 0 | F15: 1.605292 | G15: 2.653859
A16: Green P-value = significant (p<0.05) Amber = not significant
A18: BUSINESS INTERPRETATION
A19: Equation: Monthly Sales = 560,777 + 2.13 × Marketing Spend
A20: Each ₹1 of marketing spend is associated with about ₹2.13 of additional sales.
A21: Marketing spend alone explains only 16.7% of sales variation (R²=0.1672). Significant (p<0.001) but weak.
A22: Verdict: statistically significant but of limited standalone predictive value — useful only as part of a larger model.

Sheet 6. Multiple Regression
A1: MULTIPLE REGRESSION — Sales vs 4 numeric drivers + Store Type
A3: MODEL FIT
A4: Observations | B4: 320
A5: R² | B5: 0.8214
A6: Adjusted R² | B6: 0.8174
A7: F-statistic | B7: 204.9779
A8: Prob (F-statistic) | B8: 1.14e-112
A9: Residual Std Error (RMSE) | B9: 44345.22
A10: AIC | B10: 7763.87
A12: COEFFICIENTS
A13: Term | B13: Coefficient | C13: Std Error | D13: t-stat | E13: P-value | F13: 95% CI Low | G13: 95% CI High
A14: Intercept | B14: 136913.65 | C14: 43429.51 | D14: 3.1525 | E14: 0.001776 | F14: 51461.895 | G14: 222365.4
A15: Footfall | B15: 33.664405 | C15: 1.030834 | D15: 32.6574 | E15: 0 | F15: 31.636139 | G15: 35.692671
A16: Marketing Spend | B16: 1.165493 | C16: 0.128487 | D16: 9.0709 | E16: 0 | F16: 0.912682 | G16: 1.418304
A17: Avg Discount % | B17: -58920.807 | C17: 36743.021 | D17: -1.6036 | E17: 0.109816 | F17: -131216.25 | G17: 13374.632
A18: Inventory Availability % | B18: 3001.1957 | C18: 466.59755 | D18: 6.4321 | E18: 0 | F18: 2083.12 | G18: 3919.2714
A19: Store Type = Airport | B19: 21905.715 | C19: 9402.0876 | D19: 2.3299 | E19: 0.02045 | F19: 3406.2 | G19: 40405.229
A20: Store Type = Mall | B20: 11433.464 | C20: 6578.0772 | D20: 1.7381 | E20: 0.083177 | F20: -1509.5379 | G20: 24376.465
A21: Store Type = Residential | B21: -16575.848 | C21: 6085.6267 | D21: -2.7238 | E21: 0.006818 | F21: -28549.905 | G21: -4601.79
A22: Green P-value = significant (p<0.05) Amber = not significant
A24: BUSINESS INTERPRETATION
A25: Adjusted R² = 0.8174 — the model explains ~82% of sales variation. F=205, p<0.001 (jointly highly significant).
A26: Footfall, Marketing Spend and Inventory Availability are all highly significant (p<0.001) and positive — the core controllable drivers.
A27: Avg Discount % is NOT significant (p=0.11) — deeper discounting shows no reliable sales lift here; do not over-interpret.
A28: vs an identical High Street store: Airport +₹21,906 (sig), Residential −₹16,576 (sig), Mall +₹11,433 (borderline, p=0.08).
A29: All VIFs ≈ 1 — no multicollinearity, so each coefficient can be read independently.

Sheet 7. Predictions
A1: PREDICTIONS & RESIDUALS (predicted sales computed live from model coefficients)
A2: Predicted = Intercept + Σ(coef × value). Residual = Actual − Predicted. Cells recalc if coefficients change.
A4: store_id | B4: month | C4: region | D4: store_type | E4: footfall | F4: marketing_spend | G4: avg_discount_pct | H4: inventory_availability_pct | I4: st_Airport | J4: st_Mall | K4: st_Residential | L4: actual_sales | M4: predicted_sales | N4: residual | O4: abs_residual | P4: residual_%
A5: STR-1001 | B5: 2025-01 | C5: East | D5: Residential | E5: 8302 | F5: 70389.11 | G5: 0.042 | H5: 75 | I5: 0 | J5: 0 | K5: 1 | L5: 658832.62 | M5: ='6. Multiple Regression'!$B$14+'6. Multiple Regression'!$B$15*E5+'6. Multiple Regression'!$B$16*F5+'6. Multiple Regression'!$B$17*G5+'6. Multiple Regression'!$B$18*H5+'6. Multiple Regression'!$B$19*I5+'6. Multiple Regression'!$B$20*J5+'6. Multiple Regression'!$B$21*K5 -> 704472.71 | N5: =L5-M5 -> -45640.088 | O5: =ABS(N5) -> 45640.088 | P5: =N5/L5 -> -0.069274178
A6: STR-1001 | B6: 2025-02 | C6: East | D6: Residential | E6: 8487 | F6: 43827.89 | G6: 0.168 | H6: 84.4 | I6: 0 | J6: 0 | K6: 1 | L6: 634436 | M6: ='6. Multiple Regression'!$B$14+'6. Multiple Regression'!$B$15*E6+'6. Multiple Regression'!$B$16*F6+'6. Multiple Regression'!$B$17*G6+'6. Multiple Regression'!$B$18*H6+'6. Multiple Regression'!$B$19*I6+'6. Multiple Regression'!$B$20*J6+'6. Multiple Regression'!$B$21*K6 -> 700530.93 | N6: =L6-M6 -> -66094.925 | O6: =ABS(N6) -> 66094.925 | P6: =N6/L6 -> -0.10417903
A7: STR-1001 | B7: 2025-03 | C7: East | D7: Residential | E7: 9113 | F7: 59921.75 | G7: 0.133 | H7: 88 | I7: 0 | J7: 0 | K7: 1 | L7: 678722.06 | M7: ='6. Multiple Regression'!$B$14+'6. Multiple Regression'!$B$15*E7+'6. Multiple Regression'!$B$16*F7+'6. Multiple Regression'!$B$17*G7+'6. Multiple Regression'!$B$18*H7+'6. Multiple Regression'!$B$19*I7+'6. Multiple Regression'!$B$20*J7+'6. Multiple Regression'!$B$21*K7 -> 753228.66 | N7: =L7-M7 -> -74506.597 | O7: =ABS(N7) -> 74506.597 | P7: =N7/L7 -> -0.10977483
A8: STR-1001 | B8: 2025-04 | C8: East | D8: Residential | E8: 9431 | F8: 56856.63 | G8: 0.142 | H8: 86.9 | I8: 0 | J8: 0 | K8: 1 | L8: 658920.3 | M8: ='6. Multiple Regression'!$B$14+'6. Multiple Regression'!$B$15*E8+'6. Multiple Regression'!$B$16*F8+'6. Multiple Regression'!$B$17*G8+'6. Multiple Regression'!$B$18*H8+'6. Multiple Regression'!$B$19*I8+'6. Multiple Regression'!$B$20*J8+'6. Multiple Regression'!$B$21*K8 -> 756529.96 | N8: =L8-M8 -> -97609.659 | O8: =ABS(N8) -> 97609.659 | P8: =N8/L8 -> -0.14813576
A9: STR-1002 | B9: 2025-01 | C9: East | D9: High Street | E9: 9545 | F9: 48412.64 | G9: 0.231 | H9: 97.6 | I9: 0 | J9: 0 | K9: 0 | L9: 741341.44 | M9: ='6. Multiple Regression'!$B$14+'6. Multiple Regression'!$B$15*E9+'6. Multiple Regression'!$B$16*F9+'6. Multiple Regression'!$B$17*G9+'6. Multiple Regression'!$B$18*H9+'6. Multiple Regression'!$B$19*I9+'6. Multiple Regression'!$B$20*J9+'6. Multiple Regression'!$B$21*K9 -> 793970.98 | N9: =L9-M9 -> -52629.54 | O9: =ABS(N9) -> 52629.54 | P9: =N9/L9 -> -0.070992308
A10: STR-1002 | B10: 2025-02 | C10: East | D10: High Street | E10: 9792 | F10: 64811.21 | G10: 0.112 | H10: 84.2 | I10: 0 | J10: 0 | K10: 0 | L10: 761835.34 | M10: ='6. Multiple Regression'!$B$14+'6. Multiple Regression'!$B$15*E10+'6. Multiple Regression'!$B$16*F10+'6. Multiple Regression'!$B$17*G10+'6. Multiple Regression'!$B$18*H10+'6. Multiple Regression'!$B$19*I10+'6. Multiple Regression'!$B$20*J10+'6. Multiple Regression'!$B$21*K10 -> 788194.06 | N10: =L10-M10 -> -26358.72 | O10: =ABS(N10) -> 26358.72 | P10: =N10/L10 -> -0.034598973
A11: STR-1002 | B11: 2025-03 | C11: East | D11: High Street | E11: 10616 | F11: 46213.45 | G11: 0.122 | H11: 85.2 | I11: 0 | J11: 0 | K11: 0 | L11: 806615.54 | M11: ='6. Multiple Regression'!$B$14+'6. Multiple Regression'!$B$15*E11+'6. Multiple Regression'!$B$16*F11+'6. Multiple Regression'!$B$17*G11+'6. Multiple Regression'!$B$18*H11+'6. Multiple Regression'!$B$19*I11+'6. Multiple Regression'!$B$20*J11+'6. Multiple Regression'!$B$21*K11 -> 796669.96 | N11: =L11-M11 -> 9945.5815 | O11: =ABS(N11) -> 9945.5815 | P11: =N11/L11 -> 0.012330015
A12: STR-1002 | B12: 2025-04 | C12: East | D12: High Street | E12: 8567 | F12: 68148.52 | G12: 0.127 | H12: 95.6 | I12: 0 | J12: 0 | K12: 0 | L12: 850164.26 | M12: ='6. Multiple Regression'!$B$14+'6. Multiple Regression'!$B$15*E12+'6. Multiple Regression'!$B$16*F12+'6. Multiple Regression'!$B$17*G12+'6. Multiple Regression'!$B$18*H12+'6. Multiple Regression'!$B$19*I12+'6. Multiple Regression'!$B$20*J12+'6. Multiple Regression'!$B$21*K12 -> 784174.59 | N12: =L12-M12 -> 65989.666 | O12: =ABS(N12) -> 65989.666 | P12: =N12/L12 -> 0.077619901
A13: STR-1003 | B13: 2025-01 | C13: North | D13: Airport | E13: 10979 | F13: 71838.86 | G13: 0.215 | H13: 88.6 | I13: 1 | J13: 0 | K13: 0 | L13: 930581.7 | M13: ='6. Multiple Regression'!$B$14+'6. Multiple Regression'!$B$15*E13+'6. Multiple Regression'!$B$16*F13+'6. Multiple Regression'!$B$17*G13+'6. Multiple Regression'!$B$18*H13+'6. Multiple Regression'!$B$19*I13+'6. Multiple Regression'!$B$20*J13+'6. Multiple Regression'!$B$21*K13 -> 865386.52 | N13: =L13-M13 -> 65195.182 | O13: =ABS(N13) -> 65195.182 | P13: =N13/L13 -> 0.070058525
A14: STR-1003 | B14: 2025-02 | C14: North | D14: Airport | E14: 9459 | F14: 68133.44 | G14: 0.22 | H14: 85 | I14: 1 | J14: 0 | K14: 0 | L14: 779010.94 | M14: ='6. Multiple Regression'!$B$14+'6. Multiple Regression'!$B$15*E14+'6. Multiple Regression'!$B$16*F14+'6. Multiple Regression'!$B$17*G14+'6. Multiple Regression'!$B$18*H14+'6. Multiple Regression'!$B$19*I14+'6. Multiple Regression'!$B$20*J14+'6. Multiple Regression'!$B$21*K14 -> 798799.07 | N14: =L14-M14 -> -19788.133 | O14: =ABS(N14) -> 19788.133 | P14: =N14/L14 -> -0.025401611
A15: STR-1003 | B15: 2025-03 | C15: North | D15: Airport | E15: 9172 | F15: 34285.21 | G15: 0.213 | H15: 88.3 | I15: 1 | J15: 0 | K15: 0 | L15: 723060.76 | M15: ='6. Multiple Regression'!$B$14+'6. Multiple Regression'!$B$15*E15+'6. Multiple Regression'!$B$16*F15+'6. Multiple Regression'!$B$17*G15+'6. Multiple Regression'!$B$18*H15+'6. Multiple Regression'!$B$19*I15+'6. Multiple Regression'!$B$20*J15+'6. Multiple Regression'!$B$21*K15 -> 760003.91 | N15: =L15-M15 -> -36943.145 | O15: =ABS(N15) -> 36943.145 | P15: =N15/L15 -> -0.051092726
A16: STR-1003 | B16: 2025-04 | C16: North | D16: Airport | E16: 11230 | F16: 67979.88 | G16: 0.002 | H16: 85.3 | I16: 1 | J16: 0 | K16: 0 | L16: 910791.94 | M16: ='6. Multiple Regression'!$B$14+'6. Multiple Regression'!$B$15*E16+'6. Multiple Regression'!$B$16*F16+'6. Multiple Regression'!$B$17*G16+'6. Multiple Regression'!$B$18*H16+'6. Multiple Regression'!$B$19*I16+'6. Multiple Regression'!$B$20*J16+'6. Multiple Regression'!$B$21*K16 -> 871984.86 | N16: =L16-M16 -> 38807.084 | O16: =ABS(N16) -> 38807.084 | P16: =N16/L16 -> 0.042608067
... A324: STR-1080 | B324: 2025-04 | C324: East | D324: Residential | E324: 5317 | F324: 40553.11 | G324: 0.165 | H324: 84.3 | I324: 0 | J324: 0 | K324: 1 | L324: 559660.84 | M324: ='6. Multiple Regression'!$B$14+'6. Multiple Regression'!$B$15*E324+'6. Multiple Regression'!$B$16*F324+'6. Multiple Regression'!$B$17*G324+'6. Multiple Regression'!$B$18*H324+'6. Multiple Regression'!$B$19*I324+'6. Multiple Regression'!$B$20*J324+'6. Multiple Regression'!$B$21*K324 -> 589874.67 | N324: =L324-M324 -> -30213.831 | O324: =ABS(N324) -> 30213.831 | P324: =N324/L324 -> -0.053985966
A326: MODEL ERROR SUMMARY
A327: Mean Absolute Error (MAE) | B327: =AVERAGE(O5:O324) -> 34008.508
A328: Mean Actual Sales | B328: =AVERAGE(L5:L324) -> 680628.72
A329: MAPE (mean abs % error) | B329: =SUMPRODUCT(ABS(N5:N324),1/L5:L324)/COUNT(L5:L324) -> 0.051192399

Sheet 8. Model Comparison
A1: MODEL COMPARISON
A3: Model | B3: Dependent | C3: Independent variables | D3: R² | E3: Adjusted R² | F3: Significant variables | G3: Notes
A4: Simple Reg 1 | B4: monthly_sales | C4: footfall | D4: 0.7363 | E4: 0.7355 | F4: footfall | G4: Best single driver; misses other factors.
A5: Simple Reg 2 | B5: monthly_sales | C5: marketing_spend | D5: 0.1672 | E5: 0.1646 | F5: marketing_spend | G5: Weak alone; marketing matters but not in isolation.
A6: Multiple Reg | B6: monthly_sales | C6: footfall + marketing + discount + inventory + store_type | D6: 0.8214 | E6: 0.8174 | F6: footfall, marketing_spend, inventory_avail, Airport, Residential | G6: Best fit & most balanced; recommended model.
A8: RECOMMENDED MODEL: Multiple Regression — highest Adjusted R² (0.8174), all key drivers significant, no multicollinearity, MAPE ≈ 5.12%.
